<?xml version="1.0" encoding="UTF-8"?>
<!-- Generated by org.testng.reporters.JUnitReportReporter -->
<testsuite hostname="vdc01dlap0337" name="net.valtech.Assertions.HardAssertion" tests="6" failures="1" timestamp="13 Dec 2017 06:03:32 GMT" time="0.173" errors="0">
  <testcase name="assertNull" time="0.022" classname="net.valtech.Assertions.HardAssertion"/>
  <testcase name="assertTrue" time="0.022" classname="net.valtech.Assertions.HardAssertion"/>
  <testcase name="assertEquals" time="0.094" classname="net.valtech.Assertions.HardAssertion">
    <failure type="java.lang.AssertionError" message="expected [This assertion will fail] but found [assertion]">
      <![CDATA[java.lang.AssertionError: expected [This assertion will fail] but found [assertion]
	at org.testng.Assert.fail(Assert.java:94)
	at org.testng.Assert.failNotEquals(Assert.java:496)
	at org.testng.Assert.assertEquals(Assert.java:125)
	at org.testng.Assert.assertEquals(Assert.java:178)
	at org.testng.Assert.assertEquals(Assert.java:188)
	at net.valtech.Assertions.HardAssertion.assertEquals(HardAssertion.java:14)
	at sun.reflect.NativeMethodAccessorImpl.invoke0(Native Method)
	at sun.reflect.NativeMethodAccessorImpl.invoke(NativeMethodAccessorImpl.java:62)
	at sun.reflect.DelegatingMethodAccessorImpl.invoke(DelegatingMethodAccessorImpl.java:43)
	at java.lang.reflect.Method.invoke(Method.java:498)
	at org.testng.internal.MethodInvocationHelper.invokeMethod(MethodInvocationHelper.java:85)
	at org.testng.internal.Invoker.invokeMethod(Invoker.java:659)
	at org.testng.internal.Invoker.invokeTestMethod(Invoker.java:845)
	at org.testng.internal.Invoker.invokeTestMethods(Invoker.java:1153)
	at org.testng.internal.TestMethodWorker.invokeTestMethods(TestMethodWorker.java:125)
	at org.testng.internal.TestMethodWorker.run(TestMethodWorker.java:108)
	at org.testng.TestRunner.privateRun(TestRunner.java:771)
	at org.testng.TestRunner.run(TestRunner.java:621)
	at org.testng.SuiteRunner.runTest(SuiteRunner.java:357)
	at org.testng.SuiteRunner.runSequentially(SuiteRunner.java:352)
	at org.testng.SuiteRunner.privateRun(SuiteRunner.java:310)
	at org.testng.SuiteRunner.run(SuiteRunner.java:259)
	at org.testng.SuiteRunnerWorker.runSuite(SuiteRunnerWorker.java:52)
	at org.testng.SuiteRunnerWorker.run(SuiteRunnerWorker.java:86)
	at org.testng.TestNG.runSuitesSequentially(TestNG.java:1199)
	at org.testng.TestNG.runSuitesLocally(TestNG.java:1124)
	at org.testng.TestNG.run(TestNG.java:1032)
	at org.testng.remote.AbstractRemoteTestNG.run(AbstractRemoteTestNG.java:114)
	at org.testng.remote.RemoteTestNG.initAndRun(RemoteTestNG.java:251)
	at org.testng.remote.RemoteTestNG.main(RemoteTestNG.java:77)
]]>
    </failure>
  </testcase> <!-- assertEquals -->
  <testcase name="assertFalse" time="0.007" classname="net.valtech.Assertions.HardAssertion"/>
  <testcase name="assertNotEquals" time="0.009" classname="net.valtech.Assertions.HardAssertion"/>
  <testcase name="assertNotNull" time="0.019" classname="net.valtech.Assertions.HardAssertion"/>
</testsuite> <!-- net.valtech.Assertions.HardAssertion -->
